<?xml version="1.0"?>
<robot name="Franka">
    <ros2_control name="franka_hw" type="system">
        <hardware>
          <plugin>franka_coppelia_hw/FrankaEffortHardware</plugin>
          <param name="example_param_hw_start_duration_sec">0</param>
          <param name="example_param_hw_stop_duration_sec">3.0</param>
          <param name="example_param_hw_slowdown">100</param>
        </hardware>
        <joint name="panda_joint1">
          <command_interface name="effort"/>
          <state_interface name="position"/>
          <state_interface name="velocity"/>
          <state_interface name="effort"/>
        </joint>
        <joint name="panda_joint2">
          <command_interface name="effort"/>
          <state_interface name="position"/>
          <state_interface name="velocity"/>
          <state_interface name="effort"/>
        </joint>
        <joint name="panda_joint3">
          <command_interface name="effort"/>
          <state_interface name="position"/>
          <state_interface name="velocity"/>
          <state_interface name="effort"/>
        </joint>
        <joint name="panda_joint4">
          <command_interface name="effort"/>
          <state_interface name="position"/>
          <state_interface name="velocity"/>
          <state_interface name="effort"/>
        </joint>
        <joint name="panda_joint5">
          <command_interface name="effort"/>
          <state_interface name="position"/>
          <state_interface name="velocity"/>
          <state_interface name="effort"/>
        </joint>
        <joint name="panda_joint6">
          <command_interface name="effort"/>
          <state_interface name="position"/>
          <state_interface name="velocity"/>
          <state_interface name="effort"/>
        </joint>
        <joint name="panda_joint7">
          <command_interface name="effort"/>
          <state_interface name="position"/>
          <state_interface name="velocity"/>
          <state_interface name="effort"/>
        </joint>

    </ros2_control>
    <link name="robot_base">
        <collision name="Franka">
            <origin xyz="-0.291000 -0.075000 0.070000" rpy="-3.141593 3.141593 -3.141593" />
            <geometry>
                <mesh filename="$(find franka_coppelia_hw)/mesh/visual/franka_robot_base_coll_1.dae" />
            </geometry>
        </collision>
        <visual name="link">
            <origin xyz="-0.291000 -0.075000 0.070000" rpy="-3.141593 3.141593 -3.141593" />
            <geometry>
                <mesh filename="$(find franka_coppelia_hw)/mesh/visual/franka_link0_vis_1.dae" />
            </geometry>
            <material name="link0_material">
                <color rgba="1.000000 1.000000 1.000000 1.0" />
            </material>
        </visual>
    </link>
    <joint name="panda_joint1" type="revolute">
        <axis xyz="0 0 1" />
        <limit velocity="2.1749997138977" upper="2.8972465991974" lower="-2.8972465991974" effort="87.0" />
        <parent link="robot_base" />
        <child link="link2resp" />
        <origin xyz="-0.249729 -0.074988 0.000000" rpy="-3.141593 3.141593 -3.141593" />
    </joint>
    <link name="link2resp">
        <inertial>
            <origin xyz="0.000027 -0.031145 0.262891" rpy="-3.141593 3.141593 -3.141593" />
            <inertia ixx="0.23965416449794" iyz="0.046543293301451" ixz="1.3128335716866e-05" ixy="1.8036869099987e-05" izz="0.096472146190744" iyy="0.20795149177852" />
            <mass value="4.9706840515137" />
        </inertial>
        <collision name="link2_resp">
            <origin xyz="0.000023 -0.037262 0.263822" rpy="-3.141593 3.141593 -3.141593" />
            <geometry>
                <mesh filename="$(find franka_coppelia_hw)/mesh/visual/franka_link2resp_coll_1.dae" />
            </geometry>
        </collision>
        <collision name="link2_resp">
            <origin xyz="0.000023 -0.037262 0.263822" rpy="-3.141593 3.141593 -3.141593" />
            <geometry>
                <mesh filename="$(find franka_coppelia_hw)/mesh/visual/franka_link2resp_coll_2.dae" />
            </geometry>
        </collision>
        <collision name="link2_resp">
            <origin xyz="0.000023 -0.037262 0.263822" rpy="-3.141593 3.141593 -3.141593" />
            <geometry>
                <mesh filename="$(find franka_coppelia_hw)/mesh/visual/franka_link2resp_coll_3.dae" />
            </geometry>
        </collision>
        <collision name="link2_resp">
            <origin xyz="0.000023 -0.037262 0.263822" rpy="-3.141593 3.141593 -3.141593" />
            <geometry>
                <mesh filename="$(find franka_coppelia_hw)/mesh/visual/franka_link2resp_coll_4.dae" />
            </geometry>
        </collision>
        <visual name="link">
            <origin xyz="0.000023 -0.037242 0.263855" rpy="-3.141593 3.141593 -3.141593" />
            <geometry>
                <mesh filename="$(find franka_coppelia_hw)/mesh/visual/franka_link1_vis_1.dae" />
            </geometry>
            <material name="link1_material">
                <color rgba="1.000000 1.000000 1.000000 1.0" />
            </material>
        </visual>
    </link>
    <joint name="panda_joint2" type="revolute">
        <axis xyz="0 0 1" />
        <limit velocity="2.1749997138977" upper="1.7627825737" lower="-1.7627825737" effort="87.0" />
        <parent link="link2resp" />
        <child link="link3resp" />
        <origin xyz="-0.000000 -0.000000 0.333000" rpy="1.570796 3.141593 3.141593" />
    </joint>
    <link name="link3resp">
        <inertial>
            <origin xyz="0.000012 -0.070031 0.031073" rpy="-1.570796 3.141593 -3.141593" />
            <inertia ixx="0.021097005907894" iyz="0.0040788476591549" ixz="-9.6899135443004e-07" ixy="4.6746993616892e-06" izz="0.0083947222563338" iyy="0.018332235221749" />
            <mass value="0.64692598581314" />
        </inertial>
        <collision name="link3_resp">
            <origin xyz="0.000013 -0.069030 0.037184" rpy="-1.570796 3.141593 -3.141593" />
            <geometry>
                <mesh filename="$(find franka_coppelia_hw)/mesh/visual/franka_link3resp_coll_1.dae" />
            </geometry>
        </collision>
        <collision name="link3_resp">
            <origin xyz="0.000013 -0.069030 0.037184" rpy="-1.570796 3.141593 -3.141593" />
            <geometry>
                <mesh filename="$(find franka_coppelia_hw)/mesh/visual/franka_link3resp_coll_2.dae" />
            </geometry>
        </collision>
        <visual name="link">
            <origin xyz="-0.000003 -0.069076 0.037184" rpy="-1.570796 3.141593 -3.141593" />
            <geometry>
                <mesh filename="$(find franka_coppelia_hw)/mesh/visual/franka_link2_vis_1.dae" />
            </geometry>
            <material name="link2_material">
                <color rgba="1.000000 1.000000 1.000000 1.0" />
            </material>
        </visual>
    </link>
    <joint name="panda_joint3" type="revolute">
        <axis xyz="0 0 1" />
        <limit velocity="2.1749997138977" upper="2.8972465991974" lower="-2.8972465991974" effort="87.0" />
        <parent link="link3resp" />
        <child link="link4resp" />
        <origin xyz="-0.000000 0.000000 0.000000" rpy="-1.570797 3.141593 -3.141593" />
    </joint>
    <link name="link4resp">
        <inertial>
            <origin xyz="0.044418 0.025018 0.276461" rpy="-3.141592 3.141593 3.141593" />
            <inertia ixx="0.037043165158734" iyz="-0.0066345366154784" ixz="-0.012283585683442" ixy="-0.0071662360347711" izz="0.037313700213202" iyy="0.044600332011806" />
            <mass value="3.2286040782928" />
        </inertial>
        <collision name="link4_resp">
            <origin xyz="0.041373 0.028168 0.281765" rpy="-3.141592 3.141593 3.141593" />
            <geometry>
                <mesh filename="$(find franka_coppelia_hw)/mesh/visual/franka_link4resp_coll_1.dae" />
            </geometry>
        </collision>
        <collision name="link4_resp">
            <origin xyz="0.041373 0.028168 0.281765" rpy="-3.141592 3.141593 3.141593" />
            <geometry>
                <mesh filename="$(find franka_coppelia_hw)/mesh/visual/franka_link4resp_coll_2.dae" />
            </geometry>
        </collision>
        <collision name="link4_resp">
            <origin xyz="0.041373 0.028168 0.281765" rpy="-3.141592 3.141593 3.141593" />
            <geometry>
                <mesh filename="$(find franka_coppelia_hw)/mesh/visual/franka_link4resp_coll_3.dae" />
            </geometry>
        </collision>
        <collision name="link4_resp">
            <origin xyz="0.041373 0.028168 0.281765" rpy="-3.141592 3.141593 3.141593" />
            <geometry>
                <mesh filename="$(find franka_coppelia_hw)/mesh/visual/franka_link4resp_coll_4.dae" />
            </geometry>
        </collision>
        <visual name="link">
            <origin xyz="0.041158 0.028089 0.281656" rpy="-3.141592 3.141593 -3.141593" />
            <geometry>
                <mesh filename="$(find franka_coppelia_hw)/mesh/visual/franka_link3_vis_1.dae" />
            </geometry>
            <material name="link3_material">
                <color rgba="1.000000 1.000000 1.000000 1.0" />
            </material>
        </visual>
        <visual name="link">
            <origin xyz="0.041158 0.028089 0.281656" rpy="-3.141592 3.141593 -3.141593" />
            <geometry>
                <mesh filename="$(find franka_coppelia_hw)/mesh/visual/franka_link3_vis_2.dae" />
            </geometry>
            <material name="link3_material">
                <color rgba="0.250000 0.250000 0.250000 1.0" />
            </material>
        </visual>
    </link>
    <joint name="panda_joint4" type="revolute">
        <axis xyz="0 0 1" />
        <limit velocity="2.1749997138977" upper="0.0" lower="-3.0019662380219" effort="87.0" />
        <parent link="link4resp" />
        <child link="link5resp" />
        <origin xyz="0.082500 -0.000000 0.316000" rpy="-1.570796 3.141593 -3.141592" />
    </joint>
    <link name="link5resp">
        <inertial>
            <origin xyz="-0.036035 0.041072 0.024354" rpy="1.570796 3.141593 3.071779" />
            <inertia ixx="0.04844892193307" iyz="-0.0086501440884625" ixz="0.016026606898086" ixy="0.0091601974989418" izz="0.047764716548773" iyy="0.05816570900911" />
            <mass value="3.5878949165344" />
        </inertial>
        <collision name="link5_resp">
            <origin xyz="-0.038916 0.036337 0.027506" rpy="1.570796 3.141593 3.071779" />
            <geometry>
                <mesh filename="$(find franka_coppelia_hw)/mesh/visual/franka_link5resp_coll_1.dae" />
            </geometry>
        </collision>
        <collision name="link5_resp">
            <origin xyz="-0.038916 0.036337 0.027506" rpy="1.570796 3.141593 3.071779" />
            <geometry>
                <mesh filename="$(find franka_coppelia_hw)/mesh/visual/franka_link5resp_coll_2.dae" />
            </geometry>
        </collision>
        <collision name="link5_resp">
            <origin xyz="-0.038916 0.036337 0.027506" rpy="1.570796 3.141593 3.071779" />
            <geometry>
                <mesh filename="$(find franka_coppelia_hw)/mesh/visual/franka_link5resp_coll_3.dae" />
            </geometry>
        </collision>
        <collision name="link5_resp">
            <origin xyz="-0.038916 0.036337 0.027506" rpy="1.570796 3.141593 3.071779" />
            <geometry>
                <mesh filename="$(find franka_coppelia_hw)/mesh/visual/franka_link5resp_coll_4.dae" />
            </geometry>
        </collision>
        <collision name="link5_resp">
            <origin xyz="-0.038916 0.036337 0.027506" rpy="1.570796 3.141593 3.071779" />
            <geometry>
                <mesh filename="$(find franka_coppelia_hw)/mesh/visual/franka_link5resp_coll_5.dae" />
            </geometry>
        </collision>
        <collision name="link5_resp">
            <origin xyz="-0.038916 0.036337 0.027506" rpy="1.570796 3.141593 3.071779" />
            <geometry>
                <mesh filename="$(find franka_coppelia_hw)/mesh/visual/franka_link5resp_coll_6.dae" />
            </geometry>
        </collision>
        <visual name="link">
            <origin xyz="-0.039111 0.036345 0.027485" rpy="1.570796 3.141593 3.071779" />
            <geometry>
                <mesh filename="$(find franka_coppelia_hw)/mesh/visual/franka_link4_vis_1.dae" />
            </geometry>
            <material name="link4_material">
                <color rgba="1.000000 1.000000 1.000000 1.0" />
            </material>
        </visual>
        <visual name="link">
            <origin xyz="-0.039111 0.036345 0.027485" rpy="1.570796 3.141593 3.071779" />
            <geometry>
                <mesh filename="$(find franka_coppelia_hw)/mesh/visual/franka_link4_vis_2.dae" />
            </geometry>
            <material name="link4_material">
                <color rgba="0.250000 0.250000 0.250000 1.0" />
            </material>
        </visual>
    </link>
    <joint name="panda_joint5" type="revolute">
        <axis xyz="0 0 1" />
        <limit velocity="2.610000371933" upper="2.8972465991974" lower="-2.8972465991974" effort="12.0" />
        <parent link="link5resp" />
        <child link="link6resp" />
        <origin xyz="-0.055513 0.388820 -0.000000" rpy="1.570796 3.141593 3.071779" />
    </joint>
    <link name="link6resp">
        <inertial>
            <origin xyz="0.000101 0.038651 -0.110916" rpy="3.141593 3.141592 3.141592" />
            <inertia ixx="0.03988537400492" iyz="-0.0078141474579038" ixz="-2.672442414716e-05" ixy="6.5734913571839e-07" izz="0.010430599214868" iyy="0.036230106859883" />
            <mass value="1.2259459495544" />
        </inertial>
        <collision name="link6_resp">
            <origin xyz="0.000168 0.037213 -0.105096" rpy="3.141593 3.141592 3.141592" />
            <geometry>
                <mesh filename="$(find franka_coppelia_hw)/mesh/visual/franka_link6resp_coll_1.dae" />
            </geometry>
        </collision>
        <collision name="link6_resp">
            <origin xyz="0.000168 0.037213 -0.105096" rpy="3.141593 3.141592 3.141592" />
            <geometry>
                <mesh filename="$(find franka_coppelia_hw)/mesh/visual/franka_link6resp_coll_2.dae" />
            </geometry>
        </collision>
        <collision name="link6_resp">
            <origin xyz="0.000168 0.037213 -0.105096" rpy="3.141593 3.141592 3.141592" />
            <geometry>
                <mesh filename="$(find franka_coppelia_hw)/mesh/visual/franka_link6resp_coll_3.dae" />
            </geometry>
        </collision>
        <collision name="link6_resp">
            <origin xyz="0.000168 0.037213 -0.105096" rpy="3.141593 3.141592 3.141592" />
            <geometry>
                <mesh filename="$(find franka_coppelia_hw)/mesh/visual/franka_link6resp_coll_4.dae" />
            </geometry>
        </collision>
        <collision name="link6_resp">
            <origin xyz="0.000168 0.037213 -0.105096" rpy="3.141593 3.141592 3.141592" />
            <geometry>
                <mesh filename="$(find franka_coppelia_hw)/mesh/visual/franka_link6resp_coll_5.dae" />
            </geometry>
        </collision>
        <collision name="link6_resp">
            <origin xyz="0.000168 0.037213 -0.105096" rpy="3.141593 3.141592 3.141592" />
            <geometry>
                <mesh filename="$(find franka_coppelia_hw)/mesh/visual/franka_link6resp_coll_6.dae" />
            </geometry>
        </collision>
        <collision name="link6_resp">
            <origin xyz="0.000168 0.037213 -0.105096" rpy="3.141593 3.141592 3.141592" />
            <geometry>
                <mesh filename="$(find franka_coppelia_hw)/mesh/visual/franka_link6resp_coll_7.dae" />
            </geometry>
        </collision>
        <collision name="link6_resp">
            <origin xyz="0.000168 0.037213 -0.105096" rpy="3.141593 3.141592 3.141592" />
            <geometry>
                <mesh filename="$(find franka_coppelia_hw)/mesh/visual/franka_link6resp_coll_8.dae" />
            </geometry>
        </collision>
        <collision name="link6_resp">
            <origin xyz="0.000168 0.037213 -0.105096" rpy="3.141593 3.141592 3.141592" />
            <geometry>
                <mesh filename="$(find franka_coppelia_hw)/mesh/visual/franka_link6resp_coll_9.dae" />
            </geometry>
        </collision>
        <visual name="link">
            <origin xyz="-0.000025 0.037473 -0.105129" rpy="3.141593 3.141592 3.141592" />
            <geometry>
                <mesh filename="$(find franka_coppelia_hw)/mesh/visual/franka_link5_vis_1.dae" />
            </geometry>
            <material name="link5_material">
                <color rgba="1.000000 1.000000 1.000000 1.0" />
            </material>
        </visual>
        <visual name="link">
            <origin xyz="-0.000025 0.037473 -0.105129" rpy="3.141593 3.141592 3.141592" />
            <geometry>
                <mesh filename="$(find franka_coppelia_hw)/mesh/visual/franka_link5_vis_2.dae" />
            </geometry>
            <material name="link5_material">
                <color rgba="0.250000 0.250000 0.250000 1.0" />
            </material>
        </visual>
    </link>
    <joint name="panda_joint6" type="revolute">
        <axis xyz="0 0 1" />
        <limit velocity="2.610000371933" upper="3.7524577584118" lower="-0.017453292384744" effort="12.0" />
        <parent link="link6resp" />
        <child link="link7resp" />
        <origin xyz="-0.000000 -0.000000 0.000000" rpy="-1.570796 3.141593 -3.141593" />
    </joint>
    <link name="link7resp">
        <inertial>
            <origin xyz="0.050819 0.005558 0.005395" rpy="1.570796 3.141593 3.141593" />
            <inertia ixx="0.0046587251169735" iyz="-6.1476550160376e-05" ixz="-0.00030740988325929" ixy="-0.00057744119112155" izz="0.0070729035771789" iyy="0.008643924526682" />
            <mass value="1.6665550470352" />
        </inertial>
        <collision name="link7_resp">
            <origin xyz="0.042191 0.013607 0.005347" rpy="1.570796 3.141593 3.141593" />
            <geometry>
                <mesh filename="$(find franka_coppelia_hw)/mesh/visual/franka_link7resp_coll_1.dae" />
            </geometry>
        </collision>
        <collision name="link7_resp">
            <origin xyz="0.042191 0.013607 0.005347" rpy="1.570796 3.141593 3.141593" />
            <geometry>
                <mesh filename="$(find franka_coppelia_hw)/mesh/visual/franka_link7resp_coll_2.dae" />
            </geometry>
        </collision>
        <collision name="link7_resp">
            <origin xyz="0.042191 0.013607 0.005347" rpy="1.570796 3.141593 3.141593" />
            <geometry>
                <mesh filename="$(find franka_coppelia_hw)/mesh/visual/franka_link7resp_coll_3.dae" />
            </geometry>
        </collision>
        <collision name="link7_resp">
            <origin xyz="0.042191 0.013607 0.005347" rpy="1.570796 3.141593 3.141593" />
            <geometry>
                <mesh filename="$(find franka_coppelia_hw)/mesh/visual/franka_link7resp_coll_4.dae" />
            </geometry>
        </collision>
        <collision name="link7_resp">
            <origin xyz="0.042191 0.013607 0.005347" rpy="1.570796 3.141593 3.141593" />
            <geometry>
                <mesh filename="$(find franka_coppelia_hw)/mesh/visual/franka_link7resp_coll_5.dae" />
            </geometry>
        </collision>
        <collision name="link7_resp">
            <origin xyz="0.042191 0.013607 0.005347" rpy="1.570796 3.141593 3.141593" />
            <geometry>
                <mesh filename="$(find franka_coppelia_hw)/mesh/visual/franka_link7resp_coll_6.dae" />
            </geometry>
        </collision>
        <collision name="link7_resp">
            <origin xyz="0.042191 0.013607 0.005347" rpy="1.570796 3.141593 3.141593" />
            <geometry>
                <mesh filename="$(find franka_coppelia_hw)/mesh/visual/franka_link7resp_coll_7.dae" />
            </geometry>
        </collision>
        <collision name="link7_resp">
            <origin xyz="0.042191 0.013607 0.005347" rpy="1.570796 3.141593 3.141593" />
            <geometry>
                <mesh filename="$(find franka_coppelia_hw)/mesh/visual/franka_link7resp_coll_8.dae" />
            </geometry>
        </collision>
        <collision name="link7_resp">
            <origin xyz="0.042191 0.013607 0.005347" rpy="1.570796 3.141593 3.141593" />
            <geometry>
                <mesh filename="$(find franka_coppelia_hw)/mesh/visual/franka_link7resp_coll_9.dae" />
            </geometry>
        </collision>
        <collision name="link7_resp">
            <origin xyz="0.042191 0.013607 0.005347" rpy="1.570796 3.141593 3.141593" />
            <geometry>
                <mesh filename="$(find franka_coppelia_hw)/mesh/visual/franka_link7resp_coll_10.dae" />
            </geometry>
        </collision>
        <collision name="link7_resp">
            <origin xyz="0.042191 0.013607 0.005347" rpy="1.570796 3.141593 3.141593" />
            <geometry>
                <mesh filename="$(find franka_coppelia_hw)/mesh/visual/franka_link7resp_coll_11.dae" />
            </geometry>
        </collision>
        <collision name="link7_resp">
            <origin xyz="0.042191 0.013607 0.005347" rpy="1.570796 3.141593 3.141593" />
            <geometry>
                <mesh filename="$(find franka_coppelia_hw)/mesh/visual/franka_link7resp_coll_12.dae" />
            </geometry>
        </collision>
        <collision name="link7_resp">
            <origin xyz="0.042191 0.013607 0.005347" rpy="1.570796 3.141593 3.141593" />
            <geometry>
                <mesh filename="$(find franka_coppelia_hw)/mesh/visual/franka_link7resp_coll_13.dae" />
            </geometry>
        </collision>
        <collision name="link7_resp">
            <origin xyz="0.042191 0.013607 0.005347" rpy="1.570796 3.141593 3.141593" />
            <geometry>
                <mesh filename="$(find franka_coppelia_hw)/mesh/visual/franka_link7resp_coll_14.dae" />
            </geometry>
        </collision>
        <collision name="link7_resp">
            <origin xyz="0.042191 0.013607 0.005347" rpy="1.570796 3.141593 3.141593" />
            <geometry>
                <mesh filename="$(find franka_coppelia_hw)/mesh/visual/franka_link7resp_coll_15.dae" />
            </geometry>
        </collision>
        <collision name="link7_resp">
            <origin xyz="0.042191 0.013607 0.005347" rpy="1.570796 3.141593 3.141593" />
            <geometry>
                <mesh filename="$(find franka_coppelia_hw)/mesh/visual/franka_link7resp_coll_16.dae" />
            </geometry>
        </collision>
        <visual name="link">
            <origin xyz="0.042086 0.013418 0.005372" rpy="1.570796 3.141593 3.141592" />
            <geometry>
                <mesh filename="$(find franka_coppelia_hw)/mesh/visual/franka_link6_vis_1.dae" />
            </geometry>
            <material name="link6_material">
                <color rgba="1.000000 1.000000 1.000000 1.0" />
            </material>
        </visual>
        <visual name="link">
            <origin xyz="0.042086 0.013418 0.005372" rpy="1.570796 3.141593 3.141592" />
            <geometry>
                <mesh filename="$(find franka_coppelia_hw)/mesh/visual/franka_link6_vis_2.dae" />
            </geometry>
            <material name="link6_material">
                <color rgba="0.250000 0.250000 0.250000 1.0" />
            </material>
        </visual>
    </link>
    <joint name="panda_joint7" type="revolute">
        <axis xyz="0 0 1" />
        <limit velocity="2.610000371933" upper="2.8972465991974" lower="-2.8972465991974" effort="12.0" />
        <parent link="link7resp" />
        <child link="link8resp" />
        <origin xyz="0.088000 0.000000 -0.000000" rpy="-1.570796 3.141592 3.141593" />
    </joint>
    <link name="link8resp">
        <inertial>
            <origin xyz="-0.000077 -0.000876 0.078618" rpy="-0.000000 3.141593 -3.141592" />
            <inertia ixx="0.0088670116631003" iyz="-9.1760218741593e-08" ixz="7.00227187462e-07" ixy="7.6321250755392e-11" izz="0.01180331651387" iyy="0.0088670122123097" />
            <mass value="0.73552197217941" />
        </inertial>
        <collision name="link8_resp">
            <origin xyz="-0.000057 -0.000873 0.103159" rpy="0.000000 3.141593 -0.595144" />
            <geometry>
                <cylinder radius="0.030879393219948" length="0.0095007419586182" />
            </geometry>
        </collision>
        <collision name="link8_resp">
            <origin xyz="-0.000079 -0.000876 0.076009" rpy="-0.000002 3.141594 -2.065463" />
            <geometry>
                <cylinder radius="0.043132938444614" length="0.045800685882568" />
            </geometry>
        </collision>
        <visual name="link">
            <origin xyz="-0.000079 -0.000877 0.080509" rpy="-0.000000 3.141593 -3.141592" />
            <geometry>
                <mesh filename="$(find franka_coppelia_hw)/mesh/visual/franka_link7_vis_1.dae" />
            </geometry>
            <material name="link7_material">
                <color rgba="1.000000 1.000000 1.000000 1.0" />
            </material>
        </visual>
    </link>
</robot>
